Workbook

Sheet Read Me
C1: 2026 Deal Filter
C2: HOW TO USE THIS WORKBOOK
B5: THE THREE QUESTIONS THIS ANSWERS
B6: Is it the right market? | C6: Demographics tab — the dashboard score and its band.
B7: Can we pay what they're asking? | C7: First Look UW — solves the maximum land price our yield supports.
B8: Should we do it? | C8: Deal Screen — nineteen criteria, weighted, with knockouts.
B10: INSTRUCTIONS
B11: Order of operations | C11: Set product type on the Deal Screen. Enter the two dashboard scores on Demographics. Build the First Look UW. Then answer the seventeen criteria.
B12: Cell convention | C12: Cream fill with blue text is an input. Grey or white cells are formula-driven — do not type over them.
B13: Answer scale | C13: Yes = 3, Maybe = 1, No = 0. Maybe is also the answer for unknown and counts toward the unknown test.
B14: Knockouts | C14: A 'No' on a KO-flagged criterion forces NO-GO regardless of score. Geography, Entitlements, Control, Brand fit, Capacity.
B15: Unknown ceiling | C15: Above 25% unknowns the verdict is INCOMPLETE. A deal we don't know enough about is not a deal we've approved.
B16: Probability | C16: A multiplier on the total, not one of the scored criteria. It ranks deals; it does not drive the verdict.
B17: Target yields | C17: Retail 7.50%, office 7.50%, multifamily 6.50%. The blended hurdle falls out of the component mix rather than being fixed at one number for every deal.
B18: Pad sales | C18: Hotel and townhome parcels are sold rather than built. Proceeds reduce our land basis, so they raise the price we can pay for the land.
B19: Structure | C19: The four buckets and all nineteen criterion names are unchanged from the retreat.

Sheet Assumptions
F1: Assumptions & Calibration
F2: EVERY SCORING LEVER LIVES HERE
B5: BUCKET WEIGHTS
B6: Bucket | C6: Weight | F6: Basis
B7: Real Estate Considerations | C7: 0.25 | F7: Market-level. Cannot be fixed by deal structure.
B8: Site Considerations | C8: 0.25 | F8: Site-level. Fixable with time and money.
B9: Deal Considerations | C9: 0.3 | F9: Process and structure. Negotiable.
B10: Toro Considerations | C10: 0.2 | F10: Internal fit. The hardest to answer honestly.
B11: Total | C11: =SUM(C7:C10) -> 1
B13: ANSWER SCALE
B14: Answer | C14: Points | F14: Meaning
B15: Yes | C15: 3 | F15: Criterion is satisfied.
B16: Maybe / Unknown | C16: 1 | F16: Uncertain or not yet diligenced. Counts toward the unknown test.
B17: No | C17: 0 | F17: Criterion fails. Forces NO-GO if knockout-flagged.
B19: VERDICT THRESHOLDS
B20: Test | C20: Value | F20: Effect
B21: GO — minimum weighted score | C21: 70 | F21: At or above this the deal is a GO.
B22: WATCH — minimum weighted score | C22: 55 | F22: Below GO but at or above this is a watchlist deal.
B23: Maximum unknown share | C23: 0.25 | F23: Above this the verdict is INCOMPLETE regardless of score.
B24: Knockout override | C24: Active | F24: Any 'No' on a KO-flagged criterion forces NO-GO.
B26: TARGET YIELD ON COST — COMPONENT BLEND
B27: Component | C27: Target YoC | F27: Basis
B28: Retail | C28: 0.075 | F28: TDC underwriting standard.
B29: Office | C29: 0.075 | F29: TDC underwriting standard.
B30: Multifamily | C30: 0.065 | F30: TDC underwriting standard.
B31: Cost load on incremental land | C31: 0.055 | F31: Financing and contingency carried on incremental land at 65% LTC.
B33: LAND VALUE CONVENTIONS — WHAT WE BUILD
B34: Component | C34: Rate | D34: Basis | F34: Note
B35: Retail | C35: 20 | D35: per SF | F35: TDC land value convention.
B36: Office | C36: 20 | D36: per SF | F36: TDC land value convention.
B37: Multifamily | C37: 40000 | D37: per unit | F37: TDC land value convention.
B39: PAD SALE RATES — WHAT WE SELL
B40: Parcel | C40: Rate | D40: Basis | F40: Note
B41: Hotel pad | C41: 20000 | D41: per key | F41: Sold, not built. Proceeds reduce land basis.
B42: Townhome pad | D42: per lot | F42: Sold, not built. Proceeds reduce land basis.
B43: Other / outparcel | D43: per parcel | F43: Sold, not built. Proceeds reduce land basis.
B45: PRODUCT TYPE CLASSIFICATION
B46: Test | C46: Value | F46: Effect
B47: Max retail share of NOI for Multifamily product | C47: 0.15 | F47: At or below this the deal tests as Multifamily. Above it, Mixed-Use.
B49: DEMOGRAPHICS DASHBOARD BANDS
...

Sheet Demographics
F1: Demographics
F2: SCORES CARRIED OVER FROM THE DASHBOARD
B5: SITE & SCORES
B6: Address run | F6: As entered in the dashboard.
B7: Radius | C7: 3 mi | F7: Three miles unless there is a reason to change it.
B8: Date pulled
B9: Mixed-Use score | F9: From the dashboard. GO ≥ 80, NO-GO ≤ 50.
B10: Multifamily score | F10: From the dashboard. GO ≥ 70, NO-GO ≤ 40.
B12: GOVERNING SCORE
B13: Product type — from Deal Screen | C13: =IF('Deal Screen'!C9="","—",'Deal Screen'!C9) -> —
B14: Governing score | C14: =IF(C13="Mixed-Use",C9,IF(C13="Multifamily",C10,""))
B15: GO threshold | C15: =IF(C13="Multifamily",Assumptions!C52,Assumptions!C51) -> 80
B16: NO-GO threshold | C16: =IF(C13="Multifamily",Assumptions!D52,Assumptions!D51) -> 50
B17: DEMOGRAPHIC BAND | C17: =IF(C14="","—",IF(C14>=C15,"GO",IF(C14<=C16,"NO-GO","WATCH"))) -> —
B19: CALIBRATION REFERENCE
B20: Site | C20: Mixed-Use | D20: Multifamily | F20: 3-mi population
B21: Avalon — Alpharetta, GA | C21: 100 | D21: 85 | F21: 70.5K
B22: Carmel, IN | C22: 101 | D22: 85 | F22: 59.9K
B23: Medley — Johns Creek, GA | C23: 93 | D23: 80 | F23: 56.6K
B24: Overlook — Cumming, GA | C24: 16 | D24: 55 | F24: 35.2K
B26: Overlook scored 16 Mixed-Use and 55 Multifamily. The dashboard ruled out mixed-use on that site; TDC delivered 301 units of multifamily.
B28: REFERENCE — DASHBOARD WEIGHTING (NO INPUT REQUIRED)
B29: Metric | C29: Mixed-Use wt | D29: Multifamily wt | F29: Note
B30: Average HH Income | C30: 30 | D30: 35 | F30: Floor metric, both types
B31: Bachelor's+ | C31: 25 | D31: 15 | F31: Floor metric, Mixed-Use
B32: Total Population | C32: 20 | D32: 25 | F32: Floor metric, both types
B33: Discretionary Spend | C33: 10 | D33: 10
B34: HH Formation | C34: 5 | D34: — | F34: Mixed-Use only
B35: Young Adult Share | C35: 5 | D35: — | F35: Mixed-Use only
B36: Rent-to-Income | C36: — | D36: 5 | F36: Multifamily only
B37: Prime Renter Age (30–44) | C37: — | D37: 5 | F37: Multifamily only
B38: Migration Signal | C38: 5 | D38: 5
B40: Mixed-Use raw scores carry a constant 1.19x scale multiplier in the dashboard. Gate multipliers apply when a floor metric falls below its soft floor.

Sheet First Look UW
H1: First Look Underwriting
H2: THE MOST WE CAN PAY FOR THE LAND
B5: Works backward. Each component's NOI and target yield imply a total cost we can carry. Subtract everything that isn't land, add back what we sell off, and what's left is the land price.
B6: STEP 1 — WHAT THE INCOME SUPPORTS
B7: Component | C7: Stabilized NOI | D7: Cost excl. land | E7: Target YoC | F7: Total cost supported | H7: Note
B8: Retail | E8: =Assumptions!$C$28 -> 0.075 | F8: =IFERROR(C8/E8,0) -> 0 | H8: All phases combined.
B9: Office | E9: =Assumptions!$C$29 -> 0.075 | F9: =IFERROR(C9/E9,0) -> 0 | H9: All phases combined.
B10: Multifamily | E10: =Assumptions!$C$30 -> 0.065 | F10: =IFERROR(C10/E10,0) -> 0 | H10: All phases combined.
B11: Total | C11: =SUM(C8:C10) -> 0 | D11: =SUM(D8:D10) -> 0 | E11: =IFERROR(C11/F11,0) -> 0 | F11: =SUM(F8:F10) -> 0 | H11: Blended hurdle implied by this component mix.
B13: STEP 2 — PARCELS WE SELL RATHER THAN BUILD
B14: Parcel | C14: Quantity | D14: Rate | E14: Proceeds | H14: Note
B15: Hotel pad (keys) | D15: =Assumptions!$C$41 -> 20000 | E15: =IFERROR(C15*D15,0) -> 0 | H15: Proceeds reduce our land basis.
B16: Townhome pad (lots) | D16: =Assumptions!$C$42 -> 0 | E16: =IFERROR(C16*D16,0) -> 0 | H16: Proceeds reduce our land basis.
B17: Other / outparcel | D17: =Assumptions!$C$43 -> 0 | E17: =IFERROR(C17*D17,0) -> 0 | H17: Proceeds reduce our land basis.
B18: Total pad sale proceeds | E18: =SUM(E15:E17) -> 0
B20: STEP 3 — THE MOST WE CAN PAY FOR THE LAND
B21: Total cost the income supports | C21: =F11 -> 0
B22: Less: everything except land | C22: =-D11 -> 0 | H22: Hard costs, soft costs, contingency, financing.
B23: Plus: pad sale proceeds | C23: =E18 -> 0 | H23: Recovered basis from parcels we sell.
B24: Land value before carry | C24: =C21+C22+C23 -> 0
B25: Less: financing & contingency on land | C25: =Assumptions!C31 -> 0.055 | H25: Incremental land is levered too.
B26: Maximum land price | C26: =C24/(1+C25) -> 0 | H26: The number to negotiate against.
B28: STEP 4 — AGAINST THE ASKING PRICE
B29: Asking price / land basis | H29: What the seller wants, or the basis in the model.
B30: Headroom / (shortfall) | C30: =IF(C29=0,0,C26-C29) -> 0
B31: Headroom as % of ask | C31: =IFERROR(C30/C29,0) -> 0
B32: Site acreage | H32: Needed for the per-acre check.
B33: Maximum land price per acre | C33: =IFERROR(C26/C32,0) -> 0
B34: LAND TEST | C34: =IF(C29=0,"—",IF(C26>=C29,"PASS","FAIL")) -> —
B36: SANITY CHECKS
B37: Component | C37: Quantity | D37: TDC rate | E37: Land at TDC rates | H37: Note
B38: Retail (SF) | D38: =Assumptions!$C$35 -> 20 | E38: =IFERROR(C38*D38,0) -> 0 | H38: What we would normally pay for this component.
B39: Office (SF) | D39: =Assumptions!$C$36 -> 20 | E39: =IFERROR(C39*D39,0) -> 0 | H39: What we would normally pay for this component.
B40: Multifamily (units) | D40: =Assumptions!$C$37 -> 40000 | E40: =IFERROR(C40*D40,0) -> 0 | H40: What we would normally pay for this component.
B41: Land at TDC standard rates | E41: =SUM(E38:E40) -> 0
B42: Maximum land price vs. TDC rates | C42: =C26-E41 -> 0 | H42: A large gap either way is worth explaining before pursuing.
B43: Retail share of NOI | C43: =IFERROR(C8/C11,0) -> 0 | H43: At or below 15% this tests as Multifamily product.
B44: Product type test suggests | C44: =IF(C11=0,"—",IF(C43<=Assumptions!C47,"Multifamily","Mixed-Use")) -> — | H44: Set the governing product type on the Deal Screen.
B46: SENSITIVITY — MAXIMUM LAND PRICE
B47: Commercial target yield across the top. Multifamily target yield down the side.
...

Sheet Deal Screen
K1: Deal Screen
K2: WEIGHTED SCORING AND GO / NO-GO VERDICT
B5: DEAL INFORMATION | H5: SCREEN RESULT
B6: Deal name | H6: Weighted screen score | I6: =SUM(F15:F36) -> 0
B7: Address / location | H7: Criteria answered (of 17) | I7: =COUNTIF(C15:C36,"Yes")+COUNTIF(C15:C36,"Maybe")+COUNTIF(C15:C36,"No") -> 0
B8: Submarket | H8: Unknown share | I8: =IFERROR(COUNTIF(C15:C36,"Maybe")/I7,0) -> 0
B9: Product type | H9: Knockout check | I9: =IF(SUMPRODUCT((G15:G36="KO")*(C15:C36="No"))>0,"FAIL","PASS") -> PASS
B10: Screen date | H10: Demographic band | I10: =Demographics!C17 -> —
B11: Prepared by | H11: SCREEN VERDICT | I11: =IF(I7<17,"NOT SCORED",IF(I9="FAIL","NO-GO",IF(I10="NO-GO","NO-GO",IF(I8>Assumptions!$C$23,"INCOMPLETE",IF(I6>=Assumptions!$C$21,"GO",IF(I6>=Assumptions!$C$22,"WATCH","NO-GO")))))) -> NOT SCORED
B13: Criterion | C13: Answer | D13: Pts | E13: Wt | F13: Score | G13: KO | K13: What it tests
B14: Real Estate Considerations
B15: Demographics | C15: =Demographics!C17 -> — | D15: =IF(Demographics!C14="","",MIN(3,Demographics!C14/100*3)) | E15: 10 | F15: =IFERROR(D15/3*E15,0) -> 0 | K15: Carried from the Demographics tab.
B16: Geography | D16: =IF(C16="Yes",Assumptions!$C$15,IF(C16="Maybe",Assumptions!$C$16,IF(C16="No",Assumptions!$C$17,""))) | E16: 5 | F16: =IFERROR(D16/3*E16,0) -> 0 | G16: KO | K16: Drive time from Alpharetta. Platform reach.
B17: Market | D17: =IF(C17="Yes",Assumptions!$C$15,IF(C17="Maybe",Assumptions!$C$16,IF(C17="No",Assumptions!$C$17,""))) | E17: 6 | F17: =IFERROR(D17/3*E17,0) -> 0 | K17: Absorption, rent growth and supply pipeline by component.
B18: Location | D18: =IF(C18="Yes",Assumptions!$C$15,IF(C18="Maybe",Assumptions!$C$16,IF(C18="No",Assumptions!$C$17,""))) | E18: 4 | F18: =IFERROR(D18/3*E18,0) -> 0 | K18: Intersection, visibility, traffic, demand generators.
B19: Site Considerations
B20: Barriers to Entry | D20: =IF(C20="Yes",Assumptions!$C$15,IF(C20="Maybe",Assumptions!$C$16,IF(C20="No",Assumptions!$C$17,""))) | E20: 6 | F20: =IFERROR(D20/3*E20,0) -> 0 | K20: Can this be replicated a mile away within 24 months?
B21: Entitlements | D21: =IF(C21="Yes",Assumptions!$C$15,IF(C21="Maybe",Assumptions!$C$16,IF(C21="No",Assumptions!$C$17,""))) | E21: 9 | F21: =IFERROR(D21/3*E21,0) -> 0 | G21: KO | K21: Zoning gap, jurisdiction posture, months to approval.
B22: Competition | D22: =IF(C22="Yes",Assumptions!$C$15,IF(C22="Maybe",Assumptions!$C$16,IF(C22="No",Assumptions!$C$17,""))) | E22: 5 | F22: =IFERROR(D22/3*E22,0) -> 0 | K22: Existing plus announced pipeline.
B23: Physical | D23: =IF(C23="Yes",Assumptions!$C$15,IF(C23="Maybe",Assumptions!$C$16,IF(C23="No",Assumptions!$C$17,""))) | E23: 5 | F23: =IFERROR(D23/3*E23,0) -> 0 | K23: Topo, wetlands, Phase I, utilities, access, assemblage.
B24: Deal Considerations
B25: Seller Sophistication | D25: =IF(C25="Yes",Assumptions!$C$15,IF(C25="Maybe",Assumptions!$C$16,IF(C25="No",Assumptions!$C$17,""))) | E25: 3 | F25: =IFERROR(D25/3*E25,0) -> 0 | K25: Cuts both ways — clean process versus fully priced.
B26: Control | D26: =IF(C26="Yes",Assumptions!$C$15,IF(C26="Maybe",Assumptions!$C$16,IF(C26="No",Assumptions!$C$17,""))) | E26: 8 | F26: =IFERROR(D26/3*E26,0) -> 0 | G26: KO | K26: DD period, extensions, soft deposit through entitlement.
B27: Market viability of all products | D27: =IF(C27="Yes",Assumptions!$C$15,IF(C27="Maybe",Assumptions!$C$16,IF(C27="No",Assumptions!$C$17,""))) | E27: 7 | F27: =IFERROR(D27/3*E27,0) -> 0 | K27: Every component must clear independently.
B28: Partner Quality | D28: =IF(C28="Yes",Assumptions!$C$15,IF(C28="Maybe",Assumptions!$C$16,IF(C28="No",Assumptions!$C$17,""))) | E28: 4 | F28: =IFERROR(D28/3*E28,0) -> 0 | K28: JV equity, co-developer or municipal partner.
B29: Pursuit costs | D29: =IF(C29="Yes",Assumptions!$C$15,IF(C29="Maybe",Assumptions!$C$16,IF(C29="No",Assumptions!$C$17,""))) | E29: 3 | F29: =IFERROR(D29/3*E29,0) -> 0 | K29: Cash to a real go / no-go, and dead-deal exposure.
B30: Timing | D30: =IF(C30="Yes",Assumptions!$C$15,IF(C30="Maybe",Assumptions!$C$16,IF(C30="No",Assumptions!$C$17,""))) | E30: 5 | F30: =IFERROR(D30/3*E30,0) -> 0 | K30: Capital markets window, delivery against competing supply.
B31: Probability | C31: 0.75 | K31: A multiplier on the total, not a scored criterion.
B32: Toro Considerations
B33: Brand fit | D33: =IF(C33="Yes",Assumptions!$C$15,IF(C33="Maybe",Assumptions!$C$16,IF(C33="No",Assumptions!$C$17,""))) | E33: 5 | F33: =IFERROR(D33/3*E33,0) -> 0 | G33: KO | K33: Placemaking at community scale, or anyone's deal?
B34: Capability | D34: =IF(C34="Yes",Assumptions!$C$15,IF(C34="Maybe",Assumptions!$C$16,IF(C34="No",Assumptions!$C$17,""))) | E34: 4 | F34: =IFERROR(D34/3*E34,0) -> 0 | K34: In-house experience with this product and structure.
B35: Capacity | D35: =IF(C35="Yes",Assumptions!$C$15,IF(C35="Maybe",Assumptions!$C$16,IF(C35="No",Assumptions!$C$17,""))) | E35: 6 | F35: =IFERROR(D35/3*E35,0) -> 0 | G35: KO | K35: Medley through opening; Overlook delivering Fall 2027.
B36: Fee Potential | D36: =IF(C36="Yes",Assumptions!$C$15,IF(C36="Maybe",Assumptions!$C$16,IF(C36="No",Assumptions!$C$17,""))) | E36: 5 | F36: =IFERROR(D36/3*E36,0) -> 0 | K36: Development fee, co-invest and promote.
B38: DETAIL
B39: Unknowns | C39: =COUNTIF(C15:C36,"Maybe") -> 0
B40: Probability | C40: =C31 -> 0.75
B41: Probability-weighted score | C41: =I6*C31 -> 0
B42: Land test — First Look UW | C42: ='First Look UW'!C34 -> —
B44: Any 'No' on a KO-flagged criterion, or a NO-GO demographic band, forces NO-GO. Above the unknown ceiling the verdict is INCOMPLETE rather than score-driven.

Sheet Pipeline
K1: Pipeline Summary
K2: ONE ROW PER SCREENED DEAL
B5: Hidden by default. The first row links live to the Deal Screen; paste values into a new row as each deal is completed.
B7: Deal | C7: Submarket | D7: Product type | E7: Demo score | F7: Screen score | G7: Prob. | H7: Prob-wtd | I7: Max land price | J7: Asking price | K7: Verdict
B8: =IF('Deal Screen'!C6="","",'Deal Screen'!C6) | C8: =IF('Deal Screen'!C8="","",'Deal Screen'!C8) | D8: =IF('Deal Screen'!C9="","",'Deal Screen'!C9) | E8: =Demographics!C14 | F8: =IF('Deal Screen'!I11="NOT SCORED","",'Deal Screen'!I6) | G8: ='Deal Screen'!C31 -> 0.75 | H8: =IF('Deal Screen'!I11="NOT SCORED","",'Deal Screen'!C41) | I8: =IF('First Look UW'!C26=0,"",'First Look UW'!C26) | J8: =IF('First Look UW'!C29=0,"",'First Look UW'!C29) | K8: ='Deal Screen'!I11 -> NOT SCORED
B9: Medley | C9: Johns Creek | D9: Mixed-Use | E9: 93 | K9: Built
B10: Overlook at Cumming City Center | C10: Forsyth | D10: Multifamily | E10: 55 | K10: Built
B11: Avalon | C11: Alpharetta | D11: Mixed-Use | E11: 100 | K11: Benchmark
B12: Carmel, IN | C12: Carmel, IN | D12: Mixed-Use | E12: 101 | K12: Benchmark
